Workbook

Sheet Monthly Fund Record
A1: Janakalyan Samata Yuwa Club
A2: Monthly Membership Fund Record - one row per member, one column per month
A3: Fiscal year | C3: 2080/2081 | D3: Default monthly fund (NPR) | E3: 20 | F3: Type the amount each member actually paid. Leave a cell blank or 0 when nothing was paid.
A5: Member Name | B5: Baisakh | C5: Jestha | D5: Ashadh | E5: Shrawan | F5: Bhadra | G5: Ashwin | H5: Kartik | I5: Mangsir | J5: Poush | K5: Magh | L5: Falgun | M5: Chaitra | N5: TOTAL
A6: Example - replace this name | N6: =IF(COUNT(B6:M6)=0,"",SUM(B6:M6))
A7: Example - replace this name | N7: =IF(COUNT(B7:M7)=0,"",SUM(B7:M7))
A8: Example - replace this name | N8: =IF(COUNT(B8:M8)=0,"",SUM(B8:M8))
N9: =IF(COUNT(B9:M9)=0,"",SUM(B9:M9))
N10: =IF(COUNT(B10:M10)=0,"",SUM(B10:M10))
N11: =IF(COUNT(B11:M11)=0,"",SUM(B11:M11))
N12: =IF(COUNT(B12:M12)=0,"",SUM(B12:M12))
N13: =IF(COUNT(B13:M13)=0,"",SUM(B13:M13))
N14: =IF(COUNT(B14:M14)=0,"",SUM(B14:M14))
N15: =IF(COUNT(B15:M15)=0,"",SUM(B15:M15))
N16: =IF(COUNT(B16:M16)=0,"",SUM(B16:M16))
N17: =IF(COUNT(B17:M17)=0,"",SUM(B17:M17))
N18: =IF(COUNT(B18:M18)=0,"",SUM(B18:M18))
N19: =IF(COUNT(B19:M19)=0,"",SUM(B19:M19))
N20: =IF(COUNT(B20:M20)=0,"",SUM(B20:M20))
... N45: =IF(COUNT(B45:M45)=0,"",SUM(B45:M45))
A46: TOTAL COLLECTED | B46: =SUM(B6:B45) | C46: =SUM(C6:C45) | D46: =SUM(D6:D45) | E46: =SUM(E6:E45) | F46: =SUM(F6:F45) | G46: =SUM(G6:G45) | H46: =SUM(H6:H45) | I46: =SUM(I6:I45) | ... N46: =SUM(N6:N45)

Sheet Donation Record
A1: Janakalyan Samata Yuwa Club - Donation Record
A2: One row per donation. Only rows marked Approved count towards the confirmed total.
A4: S.N. | B4: Nepali Date | C4: English Date | D4: Donor Name | E4: Phone Number | F4: Email Address | G4: Donation Purpose | H4: Payment Method | I4: Amount (NPR) | J4: Payment Status | K4: Received By | L4: Remarks | N4: Approved total | O4: =SUMIF($J$5:$J$64,"Approved",$I$5:$I$64)
A5: =IF(COUNTA(D5:J5)=0,"",ROW()-4) | N5: Pending total | O5: =SUMIF($J$5:$J$64,"Pending",$I$5:$I$64)
A6: =IF(COUNTA(D6:J6)=0,"",ROW()-4) | N6: Rejected total | O6: =SUMIF($J$5:$J$64,"Rejected",$I$5:$I$64)
A7: =IF(COUNTA(D7:J7)=0,"",ROW()-4) | N7: Donations recorded | O7: =COUNTA($D$5:$D$64)
A8: =IF(COUNTA(D8:J8)=0,"",ROW()-4)
A9: =IF(COUNTA(D9:J9)=0,"",ROW()-4)
A10: =IF(COUNTA(D10:J10)=0,"",ROW()-4)
A11: =IF(COUNTA(D11:J11)=0,"",ROW()-4)
A12: =IF(COUNTA(D12:J12)=0,"",ROW()-4)
A13: =IF(COUNTA(D13:J13)=0,"",ROW()-4)
A14: =IF(COUNTA(D14:J14)=0,"",ROW()-4)
A15: =IF(COUNTA(D15:J15)=0,"",ROW()-4)
A16: =IF(COUNTA(D16:J16)=0,"",ROW()-4)
A17: =IF(COUNTA(D17:J17)=0,"",ROW()-4)
A18: =IF(COUNTA(D18:J18)=0,"",ROW()-4)
A19: =IF(COUNTA(D19:J19)=0,"",ROW()-4)
... A64: =IF(COUNTA(D64:J64)=0,"",ROW()-4)

Sheet Monthly Fund Summary
A1: Monthly Fund Summary
A2: These figures come straight from the Monthly Fund Record sheet - nothing is typed here.
A4: At a glance
A5: Total registered members | B5: =COUNTA('Monthly Fund Record'!A6:A45)
A6: Total monthly fund collected | B6: =SUM('Monthly Fund Record'!N6:N45)
A7: Expected fund (members x 12 x default) | B7: =COUNTA('Monthly Fund Record'!A6:A45)*12*'Monthly Fund Record'!$E$3
A8: Outstanding / unpaid fund | B8: =B7-B6
A9: Members who paid something | B9: =COUNTIF('Monthly Fund Record'!N6:N45,">0")
A10: Members who paid nothing | B10: =B5-B9
A12: Month by month
A13: Month | B13: Collected (NPR)
A14: Baisakh | B14: =SUM('Monthly Fund Record'!B6:B45)
A15: Jestha | B15: =SUM('Monthly Fund Record'!C6:C45)
A16: Ashadh | B16: =SUM('Monthly Fund Record'!D6:D45)
A17: Shrawan | B17: =SUM('Monthly Fund Record'!E6:E45)
A18: Bhadra | B18: =SUM('Monthly Fund Record'!F6:F45)
A19: Ashwin | B19: =SUM('Monthly Fund Record'!G6:G45)
A20: Kartik | B20: =SUM('Monthly Fund Record'!H6:H45)
A21: Mangsir | B21: =SUM('Monthly Fund Record'!I6:I45)
A22: Poush | B22: =SUM('Monthly Fund Record'!J6:J45)
A23: Magh | B23: =SUM('Monthly Fund Record'!K6:K45)
A24: Falgun | B24: =SUM('Monthly Fund Record'!L6:L45)
A25: Chaitra | B25: =SUM('Monthly Fund Record'!M6:M45)
A26: Yearly total | B26: =SUM(B14:B25)
A28: Member by member
A29: Member | B29: Months paid | C29: Paid (NPR) | D29: Unpaid months
A30: =IF('Monthly Fund Record'!A6="","",'Monthly Fund Record'!A6) | B30: =IF($A30="","",COUNT('Monthly Fund Record'!B6:M6)) | C30: =IF($A30="","",SUM('Monthly Fund Record'!B6:M6)) | D30: =IF($A30="","",12-COUNT('Monthly Fund Record'!B6:M6))
A31: =IF('Monthly Fund Record'!A7="","",'Monthly Fund Record'!A7) | B31: =IF($A31="","",COUNT('Monthly Fund Record'!B7:M7)) | C31: =IF($A31="","",SUM('Monthly Fund Record'!B7:M7)) | D31: =IF($A31="","",12-COUNT('Monthly Fund Record'!B7:M7))
A32: =IF('Monthly Fund Record'!A8="","",'Monthly Fund Record'!A8) | B32: =IF($A32="","",COUNT('Monthly Fund Record'!B8:M8)) | C32: =IF($A32="","",SUM('Monthly Fund Record'!B8:M8)) | D32: =IF($A32="","",12-COUNT('Monthly Fund Record'!B8:M8))
A33: =IF('Monthly Fund Record'!A9="","",'Monthly Fund Record'!A9) | B33: =IF($A33="","",COUNT('Monthly Fund Record'!B9:M9)) | C33: =IF($A33="","",SUM('Monthly Fund Record'!B9:M9)) | D33: =IF($A33="","",12-COUNT('Monthly Fund Record'!B9:M9))
A34: =IF('Monthly Fund Record'!A10="","",'Monthly Fund Record'!A10) | B34: =IF($A34="","",COUNT('Monthly Fund Record'!B10:M10)) | C34: =IF($A34="","",SUM('Monthly Fund Record'!B10:M10)) | D34: =IF($A34="","",12-COUNT('Monthly Fund Record'!B10:M10))
A35: =IF('Monthly Fund Record'!A11="","",'Monthly Fund Record'!A11) | B35: =IF($A35="","",COUNT('Monthly Fund Record'!B11:M11)) | C35: =IF($A35="","",SUM('Monthly Fund Record'!B11:M11)) | D35: =IF($A35="","",12-COUNT('Monthly Fund Record'!B11:M11))
A36: =IF('Monthly Fund Record'!A12="","",'Monthly Fund Record'!A12) | B36: =IF($A36="","",COUNT('Monthly Fund Record'!B12:M12)) | C36: =IF($A36="","",SUM('Monthly Fund Record'!B12:M12)) | D36: =IF($A36="","",12-COUNT('Monthly Fund Record'!B12:M12))
A37: =IF('Monthly Fund Record'!A13="","",'Monthly Fund Record'!A13) | B37: =IF($A37="","",COUNT('Monthly Fund Record'!B13:M13)) | C37: =IF($A37="","",SUM('Monthly Fund Record'!B13:M13)) | D37: =IF($A37="","",12-COUNT('Monthly Fund Record'!B13:M13))
A38: =IF('Monthly Fund Record'!A14="","",'Monthly Fund Record'!A14) | B38: =IF($A38="","",COUNT('Monthly Fund Record'!B14:M14)) | C38: =IF($A38="","",SUM('Monthly Fund Record'!B14:M14)) | D38: =IF($A38="","",12-COUNT('Monthly Fund Record'!B14:M14))
A39: =IF('Monthly Fund Record'!A15="","",'Monthly Fund Record'!A15) | B39: =IF($A39="","",COUNT('Monthly Fund Record'!B15:M15)) | C39: =IF($A39="","",SUM('Monthly Fund Record'!B15:M15)) | D39: =IF($A39="","",12-COUNT('Monthly Fund Record'!B15:M15))
A40: =IF('Monthly Fund Record'!A16="","",'Monthly Fund Record'!A16) | B40: =IF($A40="","",COUNT('Monthly Fund Record'!B16:M16)) | C40: =IF($A40="","",SUM('Monthly Fund Record'!B16:M16)) | D40: =IF($A40="","",12-COUNT('Monthly Fund Record'!B16:M16))
A41: =IF('Monthly Fund Record'!A17="","",'Monthly Fund Record'!A17) | B41: =IF($A41="","",COUNT('Monthly Fund Record'!B17:M17)) | C41: =IF($A41="","",SUM('Monthly Fund Record'!B17:M17)) | D41: =IF($A41="","",12-COUNT('Monthly Fund Record'!B17:M17))
... A69: =IF('Monthly Fund Record'!A45="","",'Monthly Fund Record'!A45) | B69: =IF($A69="","",COUNT('Monthly Fund Record'!B45:M45)) | C69: =IF($A69="","",SUM('Monthly Fund Record'!B45:M45)) | D69: =IF($A69="","",12-COUNT('Monthly Fund Record'!B45:M45))

Sheet Donation Summary
A1: Donation Summary
A2: Only Approved donations are counted as confirmed money received.
A4: Totals
A5: Total donations recorded | B5: =SUM('Donation Record'!I5:I64)
A6: Approved (confirmed) | B6: =SUMIF('Donation Record'!J5:J64,"Approved",'Donation Record'!I5:I64)
A7: Pending | B7: =SUMIF('Donation Record'!J5:J64,"Pending",'Donation Record'!I5:I64)
A8: Rejected | B8: =SUMIF('Donation Record'!J5:J64,"Rejected",'Donation Record'!I5:I64)
A9: Number of donations | B9: =COUNTA('Donation Record'!D5:D64)
A11: Month by month (approved only)
A12: Month | B12: Approved (NPR)
A13: Baisakh | B13: =SUMPRODUCT((MONTH('Donation Record'!$C$5:$C$64)=1)*('Donation Record'!$J$5:$J$64="Approved")*('Donation Record'!$I$5:$I$64))
A14: Jestha | B14: =SUMPRODUCT((MONTH('Donation Record'!$C$5:$C$64)=2)*('Donation Record'!$J$5:$J$64="Approved")*('Donation Record'!$I$5:$I$64))
A15: Ashadh | B15: =SUMPRODUCT((MONTH('Donation Record'!$C$5:$C$64)=3)*('Donation Record'!$J$5:$J$64="Approved")*('Donation Record'!$I$5:$I$64))
A16: Shrawan | B16: =SUMPRODUCT((MONTH('Donation Record'!$C$5:$C$64)=4)*('Donation Record'!$J$5:$J$64="Approved")*('Donation Record'!$I$5:$I$64))
A17: Bhadra | B17: =SUMPRODUCT((MONTH('Donation Record'!$C$5:$C$64)=5)*('Donation Record'!$J$5:$J$64="Approved")*('Donation Record'!$I$5:$I$64))
A18: Ashwin | B18: =SUMPRODUCT((MONTH('Donation Record'!$C$5:$C$64)=6)*('Donation Record'!$J$5:$J$64="Approved")*('Donation Record'!$I$5:$I$64))
A19: Kartik | B19: =SUMPRODUCT((MONTH('Donation Record'!$C$5:$C$64)=7)*('Donation Record'!$J$5:$J$64="Approved")*('Donation Record'!$I$5:$I$64))
A20: Mangsir | B20: =SUMPRODUCT((MONTH('Donation Record'!$C$5:$C$64)=8)*('Donation Record'!$J$5:$J$64="Approved")*('Donation Record'!$I$5:$I$64))
A21: Poush | B21: =SUMPRODUCT((MONTH('Donation Record'!$C$5:$C$64)=9)*('Donation Record'!$J$5:$J$64="Approved")*('Donation Record'!$I$5:$I$64))
A22: Magh | B22: =SUMPRODUCT((MONTH('Donation Record'!$C$5:$C$64)=10)*('Donation Record'!$J$5:$J$64="Approved")*('Donation Record'!$I$5:$I$64))
A23: Falgun | B23: =SUMPRODUCT((MONTH('Donation Record'!$C$5:$C$64)=11)*('Donation Record'!$J$5:$J$64="Approved")*('Donation Record'!$I$5:$I$64))
A24: Chaitra | B24: =SUMPRODUCT((MONTH('Donation Record'!$C$5:$C$64)=12)*('Donation Record'!$J$5:$J$64="Approved")*('Donation Record'!$I$5:$I$64))
A26: By purpose (approved only)
A27: Purpose | B27: Approved (NPR)
A28: General | B28: =SUMIFS('Donation Record'!$I$5:$I$64,'Donation Record'!$G$5:$G$64,$A28,'Donation Record'!$J$5:$J$64,"Approved")
A29: Education | B29: =SUMIFS('Donation Record'!$I$5:$I$64,'Donation Record'!$G$5:$G$64,$A29,'Donation Record'!$J$5:$J$64,"Approved")
A30: Health | B30: =SUMIFS('Donation Record'!$I$5:$I$64,'Donation Record'!$G$5:$G$64,$A30,'Donation Record'!$J$5:$J$64,"Approved")
A31: Sports | B31: =SUMIFS('Donation Record'!$I$5:$I$64,'Donation Record'!$G$5:$G$64,$A31,'Donation Record'!$J$5:$J$64,"Approved")
A32: Disaster relief | B32: =SUMIFS('Donation Record'!$I$5:$I$64,'Donation Record'!$G$5:$G$64,$A32,'Donation Record'!$J$5:$J$64,"Approved")
A33: Infrastructure | B33: =SUMIFS('Donation Record'!$I$5:$I$64,'Donation Record'!$G$5:$G$64,$A33,'Donation Record'!$J$5:$J$64,"Approved")
A34: Environment | B34: =SUMIFS('Donation Record'!$I$5:$I$64,'Donation Record'!$G$5:$G$64,$A34,'Donation Record'!$J$5:$J$64,"Approved")
A35: Other | B35: =SUMIFS('Donation Record'!$I$5:$I$64,'Donation Record'!$G$5:$G$64,$A35,'Donation Record'!$J$5:$J$64,"Approved")
A37: By donor (approved only) - type a donor name in column A
A38: Donor | B38: Approved (NPR)
B39: =IF($A39="","",SUMIFS('Donation Record'!$I$5:$I$64,'Donation Record'!$D$5:$D$64,$A39,'Donation Record'!$J$5:$J$64,"Approved"))
B40: =IF($A40="","",SUMIFS('Donation Record'!$I$5:$I$64,'Donation Record'!$D$5:$D$64,$A40,'Donation Record'!$J$5:$J$64,"Approved"))
B41: =IF($A41="","",SUMIFS('Donation Record'!$I$5:$I$64,'Donation Record'!$D$5:$D$64,$A41,'Donation Record'!$J$5:$J$64,"Approved"))
B42: =IF($A42="","",SUMIFS('Donation Record'!$I$5:$I$64,'Donation Record'!$D$5:$D$64,$A42,'Donation Record'!$J$5:$J$64,"Approved"))
B43: =IF($A43="","",SUMIFS('Donation Record'!$I$5:$I$64,'Donation Record'!$D$5:$D$64,$A43,'Donation Record'!$J$5:$J$64,"Approved"))
B44: =IF($A44="","",SUMIFS('Donation Record'!$I$5:$I$64,'Donation Record'!$D$5:$D$64,$A44,'Donation Record'!$J$5:$J$64,"Approved"))
...
